Workbook
Name _Toc464338185: 'TABLA RetFte'!$A$16

Sheet Grupos Familiares
A1: GERMÁN TULIO FERNÁNDEZ FERNÁNDEZ
A2: GRUPOS FAMILIARES | I2: ENVIADO | L2: RETENCIÓN EN LA FUENTE
A3: PRESUPUESTO DE COBROS | I3: SIN ENVIAR
A4: AÑO GRAVABLE 2024 | O4: RETENCIÓN FUENTE -Honorarios- | P4: UVT 2025
B5: =+A583 -> GRAN TOTAL | C5: =+C583 -> 121229000 | D5: =+D583 -> 23033510 | E5: =+E583 -> -12447490 | F5: =+F583 -> 144262510 | G5: =+G583 -> 131815020 | H5: =+H583 -> 96430000 | I5: =+I583 -> 228245020 | O5: 0.11 | P5: 49799
A6: No. | B6: APELLIDOS Y NOMBRES o RAZÓN SOCIAL | C6: VALOR FACTURA | D6: I V A | E6: RETENCIÓN EN LA FUENTE | F6: VALOR FACTURA antes de RTE FTE | G6: VALOR TOTAL NETO DE LA FACTURA | H6: VALOR CUENTA DE COBRO | I6: VALOR NETO TOTAL FRAS + C DE C | J6: OBSERVACIONES | L6: SEGURIDAD SOCIAL | M6: Ingreso Base RetFte | N6: AGENTE RETENEDOR | O6: RETENCIÓN EN LA FUENTE | P6: Vr Ingreso Base RetFte EN UVT
L7: =12.5%+16% -> 0.285
A8: FAMILIA RESTREPO POSADA
B10: Luís Emilio
A11: 1 | B11: ÁLVAREZ LONDOÑO OLGA STELLA | C11: =SUMIF('Consolidado Cobros'!$B$10:$B$314,B11,'Consolidado Cobros'!$F$10:$F$314) -> 0 | D11: =SUMIF('Consolidado Cobros'!$B$10:$B$314,B11,'Consolidado Cobros'!$G$10:$G$314) -> 0 | E11: =SUMIF('Consolidado Cobros'!$B$10:$B$314,B11,'Consolidado Cobros'!$H$10:$H$314) -> 0 | F11: =SUMIF('Consolidado Cobros'!$B$10:$B$314,B11,'Consolidado Cobros'!$I$10:$I$314) -> 0 | G11: =SUMIF('Consolidado Cobros'!$B$10:$B$314,B11,'Consolidado Cobros'!$J$10:$J$314) -> 0 | H11: =SUMIF('Consolidado Cobros'!$B$10:$B$314,B11,'Consolidado Cobros'!$L$10:$L$314) -> 1010000 | I11: =+G11+H11 -> 1010000
A12: SUB TOTAL | C12: =SUM(C9:C11) -> 0 | D12: =SUM(D9:D11) -> 0 | E12: =IF(O12="NO RETENCIÓN",0,-O12) -> 0 | F12: =SUM(F9:F11) -> 0 | G12: =SUM(G9:G11) -> 0 | H12: =SUM(H9:H11) -> 1010000 | I12: =SUM(I9:I11) -> 1010000 | L12: =+C12*$L$7 -> 0 | M12: =+C12-L12*0 -> 0 | N12: N | O12: =IF(N12="S",M12*$O$5,"NO RETENCIÓN") -> NO RETENCIÓN | P12: =+M12/$P$5 -> 0
B14: INVERSIONES LUÍS EMILIO RESTREPO ÁLVAREZ LIMITADA | J14: Luís Emilio
A15: 1 | B15: RESTREPO ÁLVAREZ LUÍS EMILIO | C15: =SUMIF('Consolidado Cobros'!$B$10:$B$314,B15,'Consolidado Cobros'!$F$10:$F$314) -> 800000 | D15: =SUMIF('Consolidado Cobros'!$B$10:$B$314,B15,'Consolidado Cobros'!$G$10:$G$314) -> 152000 | E15: =SUMIF('Consolidado Cobros'!$B$10:$B$314,B15,'Consolidado Cobros'!$H$10:$H$314) -> -88000 | F15: =SUMIF('Consolidado Cobros'!$B$10:$B$314,B15,'Consolidado Cobros'!$I$10:$I$314) -> 952000 | G15: =SUMIF('Consolidado Cobros'!$B$10:$B$314,B15,'Consolidado Cobros'!$J$10:$J$314) -> 864000 | H15: =SUMIF('Consolidado Cobros'!$B$10:$B$314,B15,'Consolidado Cobros'!$L$10:$L$314) -> 0 | I15: =+G15+H15 -> 864000 | J15: GTFF-172
A16: =A15+1 -> 2 | B16: INVERSIONES LUÍS EMILIO RESTREPO ÁLVAREZ LIMITADA | C16: =SUMIF('Consolidado Cobros'!$B$10:$B$314,B16,'Consolidado Cobros'!$F$10:$F$314) -> 3876000 | D16: =SUMIF('Consolidado Cobros'!$B$10:$B$314,B16,'Consolidado Cobros'!$G$10:$G$314) -> 736440 | E16: =SUMIF('Consolidado Cobros'!$B$10:$B$314,B16,'Consolidado Cobros'!$H$10:$H$314) -> -426360 | F16: =SUMIF('Consolidado Cobros'!$B$10:$B$314,B16,'Consolidado Cobros'!$I$10:$I$314) -> 4612440 | G16: =SUMIF('Consolidado Cobros'!$B$10:$B$314,B16,'Consolidado Cobros'!$J$10:$J$314) -> 4186080 | H16: =SUMIF('Consolidado Cobros'!$B$10:$B$314,B16,'Consolidado Cobros'!$L$10:$L$314) -> 0 | I16: =+G16+H16 -> 4186080 | J16: GTFF-172
A17: SUB TOTAL | B17: INVERSIONES LUÍS EMILIO RESTREPO ÁLVAREZ LIMITADA | C17: =SUM(C14:C16) -> 4676000 | D17: =SUM(D14:D16) -> 888440 | E17: =SUM(E15:E16) -> -514360 | F17: =SUM(F14:F16) -> 5564440 | G17: =SUM(G14:G16) -> 5050080 | H17: =SUM(H14:H16) -> 0 | I17: =SUM(I14:I16) -> 5050080 | L17: =+C17*$L$7 -> 1332660 | M17: =+C17-L17*0 -> 4676000 | N17: S | O17: =IF(N17="S",M17*$O$5,"NO RETENCIÓN") -> 514360 | P17: =+M17/$P$5 -> 93.897468
B19: Doña Silvia | V19: -0.06302521
B20: RESTREPO POSADA SILVIA ELENA | J20: Doña Silvia
A21: 1 | B21: RESTREPO POSADA SILVIA ELENA | C21: =SUMIF('Consolidado Cobros'!$B$10:$B$314,B21,'Consolidado Cobros'!$F$10:$F$314) -> 2530000 | D21: =SUMIF('Consolidado Cobros'!$B$10:$B$314,B21,'Consolidado Cobros'!$G$10:$G$314) -> 480700 | E21: =SUMIF('Consolidado Cobros'!$B$10:$B$314,B21,'Consolidado Cobros'!$H$10:$H$314) -> 0 | F21: =SUMIF('Consolidado Cobros'!$B$10:$B$314,B21,'Consolidado Cobros'!$I$10:$I$314) -> 3010700 | G21: =SUMIF('Consolidado Cobros'!$B$10:$B$314,B21,'Consolidado Cobros'!$J$10:$J$314) -> 3010700 | H21: =SUMIF('Consolidado Cobros'!$B$10:$B$314,B21,'Consolidado Cobros'!$L$10:$L$314) -> 0 | I21: =+G21+H21 -> 3010700 | J21: GTFF-171 | Q21: =+'Facturas año anterior'!F25 -> 2380000 | R21: =+Q21*5.2% -> 123760 | S21: =+Q21+R21 -> 2503760 | T21: =+C21 -> 2530000 | U21: =+Q21-T21 -> -150000 | V21: =+U21/Q21 -> -0.06302521
A22: SUB TOTAL | C22: =SUM(C18:C21) -> 2530000 | D22: =SUM(D18:D21) -> 480700 | E22: =SUM(E21) -> 0 | F22: =SUM(F18:F21) -> 3010700 | G22: =SUM(G18:G21) -> 3010700 | H22: =SUM(H18:H21) -> 0 | I22: =SUM(I18:I21) -> 3010700 | L22: =+C22*$L$7 -> 721050 | M22: =+C22-L22*0 -> 2530000 | N22: N | O22: =IF(N22="S",M22*$O$5,"NO RETENCIÓN") -> NO RETENCIÓN | P22: =+M22/$P$5 -> 50.804233
B24: BETANCUR RESTREPO SARA LUISA
A25: =A21+1 -> 2 | B25: BETANCUR RESTREPO SARA LUISA | C25: =SUMIF('Consolidado Cobros'!$B$10:$B$314,B25,'Consolidado Cobros'!$F$10:$F$314) -> 1950000 | D25: =SUMIF('Consolidado Cobros'!$B$10:$B$314,B25,'Consolidado Cobros'!$G$10:$G$314) -> 370500 | E25: =SUMIF('Consolidado Cobros'!$B$10:$B$314,B25,'Consolidado Cobros'!$H$10:$H$314) -> 0 | F25: =SUMIF('Consolidado Cobros'!$B$10:$B$314,B25,'Consolidado Cobros'!$I$10:$I$314) -> 2320500 | G25: =SUMIF('Consolidado Cobros'!$B$10:$B$314,B25,'Consolidado Cobros'!$J$10:$J$314) -> 2320500 | H25: =SUMIF('Consolidado Cobros'!$B$10:$B$314,B25,'Consolidado Cobros'!$L$10:$L$314) -> 0 | I25: =+G25+H25 -> 2320500 | J25: GTFF-168 | Q25: =+'Facturas año anterior'!F10 -> 1830000 | R25: =+Q25*5.2% -> 95160 | S25: =+Q25+R25 -> 1925160 | T25: =+C25 -> 1950000 | U25: =+Q25-T25 -> -120000 | V25: =+U25/Q25 -> -0.06557377
A26: SUB TOTAL | C26: =SUM(C23:C25) -> 1950000 | D26: =SUM(D23:D25) -> 370500 | E26: =SUM(E25) -> 0 | F26: =SUM(F23:F25) -> 2320500 | G26: =SUM(G23:G25) -> 2320500 | H26: =SUM(H23:H25) -> 0 | I26: =SUM(I23:I25) -> 2320500 | L26: =+C26*$L$7 -> 555750 | M26: =+C26-L26*0 -> 1950000 | N26: N | O26: =IF(N26="S",M26*$O$5,"NO RETENCIÓN") -> NO RETENCIÓN | P26: =+M26/$P$5 -> 39.157413
B28: SOCIEDAD BETANCUR RESTREPO SAS
A29: =A25+1 -> 3 | B29: RESTREPO POSADA Y CÍA S EN C EN LIQUIDACIÓN | C29: =SUMIF('Consolidado Cobros'!$B$10:$B$314,B29,'Consolidado Cobros'!$F$10:$F$314) -> 3391000 | D29: =SUMIF('Consolidado Cobros'!$B$10:$B$314,B29,'Consolidado Cobros'!$G$10:$G$314) -> 644290 | E29: =SUMIF('Consolidado Cobros'!$B$10:$B$314,B29,'Consolidado Cobros'!$H$10:$H$314) -> -373010 | F29: =SUMIF('Consolidado Cobros'!$B$10:$B$314,B29,'Consolidado Cobros'!$I$10:$I$314) -> 4035290 | G29: =SUMIF('Consolidado Cobros'!$B$10:$B$314,B29,'Consolidado Cobros'!$J$10:$J$314) -> 3662280 | H29: =SUMIF('Consolidado Cobros'!$B$10:$B$314,B29,'Consolidado Cobros'!$L$10:$L$314) -> 0 | I29: =+G29+H29 -> 3662280 | J29: GTFF-173
A30: =A29+1 -> 4 | B30: SOCIEDAD BETANCUR RESTREPO S A S | C30: =SUMIF('Consolidado Cobros'!$B$10:$B$314,B30,'Consolidado Cobros'!$F$10:$F$314) -> 3873000 | D30: =SUMIF('Consolidado Cobros'!$B$10:$B$314,B30,'Consolidado Cobros'!$G$10:$G$314) -> 735870 | E30: =SUMIF('Consolidado Cobros'!$B$10:$B$314,B30,'Consolidado Cobros'!$H$10:$H$314) -> -426030 | F30: =SUMIF('Consolidado Cobros'!$B$10:$B$314,B30,'Consolidado Cobros'!$I$10:$I$314) -> 4608870 | G30: =SUMIF('Consolidado Cobros'!$B$10:$B$314,B30,'Consolidado Cobros'!$J$10:$J$314) -> 4182840 | H30: =SUMIF('Consolidado Cobros'!$B$10:$B$314,B30,'Consolidado Cobros'!$L$10:$L$314) -> 0 | I30: =+G30+H30 -> 4182840 | J30: GTFF-173
A31: SUB TOTAL | B31: SOCIEDAD BETANCUR RESTREPO SAS | C31: =SUM(C28:C30) -> 7264000 | D31: =SUM(D28:D30) -> 1380160 | E31: =SUM(E29:E30) -> -799040 | F31: =SUM(F28:F30) -> 8644160 | G31: =SUM(G28:G30) -> 7845120 | H31: =SUM(H28:H30) -> 0 | I31: =SUM(I28:I30) -> 7845120 | L31: =+C31*$L$7 -> 2070240 | M31: =+C31-L31*0 -> 7264000 | N31: S | O31: =IF(N31="S",M31*$O$5,"NO RETENCIÓN") -> 799040 | P31: =+M31/$P$5 -> 145.86638
A33: TOTAL DOÑA SILVIA ELENA | C33: =+C22+C26+C31 -> 11744000 | D33: =+D22+D26+D31 -> 2231360 | E33: =+E22+E26+E31 -> -799040 | F33: =+F22+F26+F31 -> 13975360 | G33: =+G22+G26+G31 -> 13176320 | H33: =+H22+H26+H31 -> 0 | I33: =+I22+I26+I31 -> 13176320
B36: INVERSIONES CIRPUL SAS | J36: Doña Clara
A37: 1 | B37: RESTREPO POSADA CLARA INÉS | C37: =SUMIF('Consolidado Cobros'!$B$10:$B$314,B37,'Consolidado Cobros'!$F$10:$F$314) -> 1830000 | D37: =SUMIF('Consolidado Cobros'!$B$10:$B$314,B37,'Consolidado Cobros'!$G$10:$G$314) -> 347700 | E37: =SUMIF('Consolidado Cobros'!$B$10:$B$314,B37,'Consolidado Cobros'!$H$10:$H$314) -> -201300 | F37: =SUMIF('Consolidado Cobros'!$B$10:$B$314,B37,'Consolidado Cobros'!$I$10:$I$314) -> 2177700 | G37: =SUMIF('Consolidado Cobros'!$B$10:$B$314,B37,'Consolidado Cobros'!$J$10:$J$314) -> 1976400 | H37: =SUMIF('Consolidado Cobros'!$B$10:$B$314,B37,'Consolidado Cobros'!$L$10:$L$314) -> 0 | I37: =+G37+H37 -> 1976400 | J37: GTFF-174
A38: =A37+1 -> 2 | B38: INVERSIONES CIRPUL S A S | C38: =SUMIF('Consolidado Cobros'!$B$10:$B$314,B38,'Consolidado Cobros'!$F$10:$F$314) -> 3876000 | D38: =SUMIF('Consolidado Cobros'!$B$10:$B$314,B38,'Consolidado Cobros'!$G$10:$G$314) -> 736440 | E38: =SUMIF('Consolidado Cobros'!$B$10:$B$314,B38,'Consolidado Cobros'!$H$10:$H$314) -> -426360 | F38: =SUMIF('Consolidado Cobros'!$B$10:$B$314,B38,'Consolidado Cobros'!$I$10:$I$314) -> 4612440 | G38: =SUMIF('Consolidado Cobros'!$B$10:$B$314,B38,'Consolidado Cobros'!$J$10:$J$314) -> 4186080 | H38: =SUMIF('Consolidado Cobros'!$B$10:$B$314,B38,'Consolidado Cobros'!$L$10:$L$314) -> 0 | I38: =+G38+H38 -> 4186080 | J38: GTFF-174
A39: SUB TOTAL | C39: =SUM(C37:C38) -> 5706000 | D39: =SUM(D37:D38) -> 1084140 | E39: =SUM(E37:E38) -> -627660 | F39: =SUM(F37:F38) -> 6790140 | G39: =SUM(G37:G38) -> 6162480 | H39: =SUM(H37:H38) -> 0 | I39: =SUM(I37:I38) -> 6162480 | L39: =+C39*$L$7 -> 1626210 | M39: =+C39-L39*0 -> 5706000 | N39: S | O39: =IF(N39="S",M39*$O$5,"NO RETENCIÓN") -> 627660 | P39: =+M39/$P$5 -> 114.58061
B41: Doña María Isabel
A42: 1 | B42: RESTREPO DE SÁNCHEZ MARÍA ISABEL | C42: =SUMIF('Consolidado Cobros'!$B$10:$B$314,B42,'Consolidado Cobros'!$F$10:$F$314) -> 1790000 | D42: =SUMIF('Consolidado Cobros'!$B$10:$B$314,B42,'Consolidado Cobros'!$G$10:$G$314) -> 340100 | E42: =SUMIF('Consolidado Cobros'!$B$10:$B$314,B42,'Consolidado Cobros'!$H$10:$H$314) -> 0 | F42: =SUMIF('Consolidado Cobros'!$B$10:$B$314,B42,'Consolidado Cobros'!$I$10:$I$314) -> 2130100 | G42: =SUMIF('Consolidado Cobros'!$B$10:$B$314,B42,'Consolidado Cobros'!$J$10:$J$314) -> 2130100 | H42: =SUMIF('Consolidado Cobros'!$B$10:$B$314,B42,'Consolidado Cobros'!$L$10:$L$314) -> 0 | I42: =+G42+H42 -> 2130100 | J42: GTFF-169 | L42: =+'Facturas año anterior'!F19 -> 1710000
A43: =A42+1 -> 2 | B43: SÁNCHEZ RESTREPO JUAN DAVID | C43: =SUMIF('Consolidado Cobros'!$B$10:$B$314,B43,'Consolidado Cobros'!$F$10:$F$314) -> 800000 | D43: =SUMIF('Consolidado Cobros'!$B$10:$B$314,B43,'Consolidado Cobros'!$G$10:$G$314) -> 152000 | E43: =SUMIF('Consolidado Cobros'!$B$10:$B$314,B43,'Consolidado Cobros'!$H$10:$H$314) -> 0 | F43: =SUMIF('Consolidado Cobros'!$B$10:$B$314,B43,'Consolidado Cobros'!$I$10:$I$314) -> 952000 | G43: =SUMIF('Consolidado Cobros'!$B$10:$B$314,B43,'Consolidado Cobros'!$J$10:$J$314) -> 952000 | H43: =SUMIF('Consolidado Cobros'!$B$10:$B$314,B43,'Consolidado Cobros'!$L$10:$L$314) -> 0 | I43: =+G43+H43 -> 952000 | J43: GTFF-169 | L43: =+'Facturas año anterior'!F30 -> 760000
A44: =+A43+1 -> 3 | B44: SÁNCHEZ RUBIO JOSÉ MARDOQUEO | C44: =SUMIF('Consolidado Cobros'!$B$10:$B$314,B44,'Consolidado Cobros'!$F$10:$F$314) -> 0 | D44: =SUMIF('Consolidado Cobros'!$B$10:$B$314,B44,'Consolidado Cobros'!$G$10:$G$314) -> 0 | E44: =SUMIF('Consolidado Cobros'!$B$10:$B$314,B44,'Consolidado Cobros'!$H$10:$H$314) -> 0 | F44: =SUMIF('Consolidado Cobros'!$B$10:$B$314,B44,'Consolidado Cobros'!$I$10:$I$314) -> 0 | G44: =SUMIF('Consolidado Cobros'!$B$10:$B$314,B44,'Consolidado Cobros'!$J$10:$J$314) -> 0 | H44: =SUMIF('Consolidado Cobros'!$B$10:$B$314,B44,'Consolidado Cobros'!$L$10:$L$314) -> 0 | I44: =+G44+H44 -> 0
A45: SUB TOTAL | C45: =SUM(C42:C44) -> 2590000 | D45: =SUM(D42:D44) -> 492100 | E45: =SUM(E42:E44) -> 0 | F45: =SUM(F42:F44) -> 3082100 | G45: =SUM(G42:G44) -> 3082100 | H45: =SUM(H42:H44) -> 0 | I45: =SUM(I42:I44) -> 3082100 | L45: =+C45*$L$7 -> 738150 | M45: =+C45-L45*0 -> 2590000 | N45: N | O45: =IF(N45="S",M45*$O$5,"NO RETENCIÓN") -> NO RETENCIÓN | P45: =+M45/$P$5 -> 52.009076
A48: =+A44+1 -> 4 | B48: SÁNCHEZ RESTREPO MARGARITA ROSA | C48: =SUMIF('Consolidado Cobros'!$B$10:$B$314,B48,'Consolidado Cobros'!$F$10:$F$314) -> 1000000 | D48: =SUMIF('Consolidado Cobros'!$B$10:$B$314,B48,'Consolidado Cobros'!$G$10:$G$314) -> 190000 | E48: =SUMIF('Consolidado Cobros'!$B$10:$B$314,B48,'Consolidado Cobros'!$H$10:$H$314) -> 0 | F48: =SUMIF('Consolidado Cobros'!$B$10:$B$314,B48,'Consolidado Cobros'!$I$10:$I$314) -> 1190000 | G48: =SUMIF('Consolidado Cobros'!$B$10:$B$314,B48,'Consolidado Cobros'!$J$10:$J$314) -> 1190000 | H48: =SUMIF('Consolidado Cobros'!$B$10:$B$314,B48,'Consolidado Cobros'!$L$10:$L$314) -> 0 | I48: =+G48+H48 -> 1190000 | J48: GTFF-170
A49: SUB TOTAL | C49: =SUM(C46:C48) -> 1000000 | D49: =SUM(D46:D48) -> 190000 | E49: =SUM(E48) -> 0 | F49: =SUM(F46:F48) -> 1190000 | G49: =SUM(G46:G48) -> 1190000 | H49: =SUM(H46:H48) -> 0 | I49: =SUM(I46:I48) -> 1190000 | L49: =+C49*$L$7 -> 285000 | M49: =+C49-L49*0 -> 1000000 | N49: N | O49: =IF(N49="S",M49*$O$5,"NO RETENCIÓN") -> NO RETENCIÓN | P49: =+M49/$P$5 -> 20.080725
B52: Don Juan José
A53: 1 | B53: RESTREPO POSADA JUAN JOSÉ | C53: =SUMIF('Consolidado Cobros'!$B$10:$B$314,B53,'Consolidado Cobros'!$F$10:$F$314) -> 1410000 | D53: =SUMIF('Consolidado Cobros'!$B$10:$B$314,B53,'Consolidado Cobros'!$G$10:$G$314) -> 267900 | E53: =SUMIF('Consolidado Cobros'!$B$10:$B$314,B53,'Consolidado Cobros'!$H$10:$H$314) -> -155100 | F53: =SUMIF('Consolidado Cobros'!$B$10:$B$314,B53,'Consolidado Cobros'!$I$10:$I$314) -> 1677900 | G53: =SUMIF('Consolidado Cobros'!$B$10:$B$314,B53,'Consolidado Cobros'!$J$10:$J$314) -> 1522800 | H53: =SUMIF('Consolidado Cobros'!$B$10:$B$314,B53,'Consolidado Cobros'!$L$10:$L$314) -> 0 | I53: =+G53+H53 -> 1522800 | J53: GTFF-166
...

Sheet Facturas
A1: =+'Grupos Familiares'!$A$1 -> GERMÁN TULIO FERNÁNDEZ FERNÁNDEZ
A2: =+'Grupos Familiares'!$A$3 -> PRESUPUESTO DE COBROS | R2: Mínima Mvto | T2: Mínima 1° Vez | V2: PARA CALCULAR EL VALOR A COBRAR POR EL PRESENTE AÑO | AP2: IPC 2024 | AQ2: Mínima Mvto -año anterior- | AR2: Mínima 1° Vez -Año anterior-
A3: FACTURACIÓN ELECTRÓNICA | R3: =ROUND(AQ3*(100%+$AP$3),-4) -> 230000 | T3: =ROUND(AR3*(100%+$AP$3),-4) -> 370000 | AP3: 0.052 | AQ3: 220000 | AR3: 350000
A4: =+'Grupos Familiares'!$A$4 -> AÑO GRAVABLE 2024 | F4: VALORES A FACTURAR -PRESENTE AÑO- | V4: PRESUPUESTOS DE COBRO: | Z4: =+$A$3 -> FACTURACIÓN ELECTRÓNICA | AP4: Vr Incrementado | AQ4: =(AQ3*(100%+$AP$3)) -> 231440 | AR4: =(AR3*(100%+$AP$3)) -> 368200
A5: PERSONAS NATURALES Y PERSONAS JURÍDICAS | G5: 0.19 | I5: 0.11 | V5: IPC | W5: 0.051 | Y5: 0.5 | AA5: =75%+80%*0 -> 0.75 | AC5: 0.15 | AE5: 0.2 | AG5: 0.1 | AI5: 0.2 | AK5: 0.3
A6: No. | B6: APELLIDOS Y NOMBRES o RAZÓN SOCIAL | C6: CÓDIGO | D6: NIT No. | E6: D. V. | F6: VALOR BRUTO A ELABORAR LA FACTURA | G6: I V A | H6: AGENTE RETENEDOR | I6: RETENCIÓN EN LA FUENTE | J6: VALOR FACTURA antes de RTE FTE | K6: VALOR A PAGAR NETO DE LA FACTURA | L6: VoBo ELABORAR Fra. | M6: FACTURA No. | N6: MEDIO | O6: FECHA | P6: ESTADO | Q6: OBSERVACIONES | R6: VALOR CUENTA DE COBRO -POR PRÉSTAMOS- | S6: CUENTA DE COBRO No. | T6: OBSERVACIONES | V6: SI o NO | W6: VALOR DECLARACIÓN RENTA | X6: SI o NO | Y6: VALOR DECLARACIÓN I AL P 2023 | Z6: SI o NO | AA6: VALOR MEDIOS MAGNÉTICOS | AB6: SI o NO | AC6: EXÓGENA MPIO MEDELLÍN | AD6: SI o NO | AE6: REG ÚNICO de BENEFICIARIOS | AF6: SI o NO | AG6: VALOR FORMATO 2516 CONSERVAR | AH6: SI o NO | AI6: VALOR FORMATO 2516 TRANSMITIR | AJ6: SI o NO | AK6: VALOR DECLARACIÓN ACTIVOS EN EL EXTERIOR | AL6: VALOR OTRAS ASESORÍAS | AM6: PRÉSTAMOS | AN6: TOTAL PRESUPUESTADO | AP6: FACTURAS y C de C
A8: PERSONAS NATURALES
A9: 1 | B9: ARBOLEDA PÉREZ DOLLY | C9: =_xlfn.XLOOKUP(B9,Códigos!$B$8:$B$406,Códigos!$A$8:$A$406,"Verificar",0) -> 52 | D9: =_xlfn.XLOOKUP(B9,'Consolidado Cobros'!$B$10:$B$312,'Consolidado Cobros'!$C$10:$C$312,"Verificar",0) -> 43431768 | E9: =IF((MOD((VALUE(MID(TEXT(D9,"000000000000000"),15,1))*3+VALUE(MID(TEXT(D9,"000000000000000"),14,1))*7+VALUE(MID(TEXT(D9,"000000000000000"),13,1))*13+VALUE(MID(TEXT(D9,"000000000000000"),12,1))*17+VALUE(MID(TEXT(D9,"000000000000000"),11,1))*19+VALUE(MID(TEXT(D9,"000000000000000"),10,1))*23+VALUE(MID(TEXT(D9,"000000000000000"),9,1))*29+VALUE(MID(TEXT(D9,"000000000000000"),8,1))*37+VALUE(MID(TEXT(D9,"000000000000000"),7,1))*41+VALUE(MID(TEXT(D9,"000000000000000"),6,1))*43+VALUE(MID(TEXT(D9,"000000000000000"),5,1))*47+VALUE(MID(TEXT(D9,"000000000000000"),4,1))*53+VALUE(MID(TEXT(D9,"000000000000000"),3,1))*59+VALUE(MID(TEXT(D9,"000000000000000"),2,1))*67+VALUE(MID(TEXT(D9,"000000000000000"),1,1))*71),11))=0,0,IF((MOD((VALUE(MID(TEXT(D9,"000000000000000"),15,1))*3+VALUE(MID(TEXT(D9,"000000000000000"),14,1))*7+VALUE(MID(TEXT(D9,"000000000000000"),13,1))*13+VALUE(MID(TEXT(D9,"000000000000000"),12,1))*17+VALUE(MID(TEXT(D9,"000000000000000"),11,1))*19+VALUE(MID(TEXT(D9,"000000000000000"),10,1))*23+VALUE(MID(TEXT(D9,"000000000000000"),9,1))*29+VALUE(MID(TEXT(D9,"000000000000000"),8,1))*37+VALUE(MID(TEXT(D9,"000000000000000"),7,1))*41+VALUE(MID(TEXT(D9,"000000000000000"),6,1))*43+VALUE(MID(TEXT(D9,"000000000000000"),5,1))*47+VALUE(MID(TEXT(D9,"000000000000000"),4,1))*53+VALUE(MID(TEXT(D9,"000000000000000"),3,1))*59+VALUE(MID(TEXT(D9,"000000000000000"),2,1))*67+VALUE(MID(TEXT(D9,"000000000000000"),1,1))*71),11))=1,1,11-(MOD((VALUE(MID(TEXT(D9,"000000000000000"),15,1))*3+VALUE(MID(TEXT(D9,"000000000000000"),14,1))*7+VALUE(MID(TEXT(D9,"000000000000000"),13,1))*13+VALUE(MID(TEXT(D9,"000000000000000"),12,1))*17+VALUE(MID(TEXT(D9,"000000000000000"),11,1))*19+VALUE(MID(TEXT(D9,"000000000000000"),10,1))*23+VALUE(MID(TEXT(D9,"000000000000000"),9,1))*29+VALUE(MID(TEXT(D9,"000000000000000"),8,1))*37+VALUE(MID(TEXT(D9,"000000000000000"),7,1))*41+VALUE(MID(TEXT(D9,"000000000000000"),6,1))*43+VALUE(MID(TEXT(D9,"000000000000000"),5,1))*47+VALUE(MID(TEXT(D9,"000000000000000"),4,1))*53+VALUE(MID(TEXT(D9,"000000000000000"),3,1))*59+VALUE(MID(TEXT(D9,"000000000000000"),2,1))*67+VALUE(MID(TEXT(D9,"000000000000000"),1,1))*71),11)))) -> 3 | F9: =+AN9 -> 510000 | G9: =+F9*$G$5 -> 96900 | H9: S | I9: =IF(H9="S",-F9*$I$5,"NO RETENCIÓN") -> -56100 | J9: =+F9+G9 -> 606900 | K9: =SUM(F9:I9) -> 550800 | M9: GTFF-187 | N9: Correo | O9: 45987 | R9: =+AM9 -> 0 | T9: Fra con -Ruiz González Álvaro H. | V9: SI | W9: =ROUND(IF(V9="SI",SUMIF('Facturas año anterior'!$B$8:$B$81,B9,'Facturas año anterior'!$V$8:$V$81)*(100%+$W$5),0),-3)+ROUND(IF(V9="SI",SUMIF('C de C año anterior'!$B$8:$B$210,B9,'C de C año anterior'!$Q$8:$Q$210)*(100%+$W$5),0),-3) -> 513000 | Y9: =ROUND(IF(X9="SI",W9*$Y$5,0),-3) -> 0 | AA9: =ROUND(IF(Z9="SI",W9*$AA$5,0),-3) -> 0 | AC9: =ROUND(IF(AB9="SI",W9*$AC$5,0),-3) -> 0 | AE9: =ROUND(IF(AD9="SI",W9*$AE$5,0),-3) -> 0 | AG9: =ROUND(IF(AF9="SI",W9*$AG$5,0),-3) -> 0 | AI9: =ROUND(IF(AH9="SI",W9*$AI$5,0),-3) -> 0 | AK9: =IF(AJ9="SI",W9*$AK$5,0) -> 0 | AL9: =SUMIF('Otras Asesorías y Préstamos'!$B$7:$B$242,B9,'Otras Asesorías y Préstamos'!$F$7:$F$242) -> 0 | AM9: =SUMIF('Otras Asesorías y Préstamos'!$B$7:$B$242,B9,'Otras Asesorías y Préstamos'!$V$7:$V$242) -> 0 | AN9: =ROUND(SUM(W9:AL9),-4) -> 510000
A10: =+A9+1 -> 2 | B10: BETANCUR RESTREPO SARA LUISA | C10: =_xlfn.XLOOKUP(B10,Códigos!$B$8:$B$406,Códigos!$A$8:$A$406,"Verificar",0) -> 56 | D10: =_xlfn.XLOOKUP(B10,'Consolidado Cobros'!$B$10:$B$312,'Consolidado Cobros'!$C$10:$C$312,"Verificar",0) -> 87082052990 | E10: =IF((MOD((VALUE(MID(TEXT(D10,"000000000000000"),15,1))*3+VALUE(MID(TEXT(D10,"000000000000000"),14,1))*7+VALUE(MID(TEXT(D10,"000000000000000"),13,1))*13+VALUE(MID(TEXT(D10,"000000000000000"),12,1))*17+VALUE(MID(TEXT(D10,"000000000000000"),11,1))*19+VALUE(MID(TEXT(D10,"000000000000000"),10,1))*23+VALUE(MID(TEXT(D10,"000000000000000"),9,1))*29+VALUE(MID(TEXT(D10,"000000000000000"),8,1))*37+VALUE(MID(TEXT(D10,"000000000000000"),7,1))*41+VALUE(MID(TEXT(D10,"000000000000000"),6,1))*43+VALUE(MID(TEXT(D10,"000000000000000"),5,1))*47+VALUE(MID(TEXT(D10,"000000000000000"),4,1))*53+VALUE(MID(TEXT(D10,"000000000000000"),3,1))*59+VALUE(MID(TEXT(D10,"000000000000000"),2,1))*67+VALUE(MID(TEXT(D10,"000000000000000"),1,1))*71),11))=0,0,IF((MOD((VALUE(MID(TEXT(D10,"000000000000000"),15,1))*3+VALUE(MID(TEXT(D10,"000000000000000"),14,1))*7+VALUE(MID(TEXT(D10,"000000000000000"),13,1))*13+VALUE(MID(TEXT(D10,"000000000000000"),12,1))*17+VALUE(MID(TEXT(D10,"000000000000000"),11,1))*19+VALUE(MID(TEXT(D10,"000000000000000"),10,1))*23+VALUE(MID(TEXT(D10,"000000000000000"),9,1))*29+VALUE(MID(TEXT(D10,"000000000000000"),8,1))*37+VALUE(MID(TEXT(D10,"000000000000000"),7,1))*41+VALUE(MID(TEXT(D10,"000000000000000"),6,1))*43+VALUE(MID(TEXT(D10,"000000000000000"),5,1))*47+VALUE(MID(TEXT(D10,"000000000000000"),4,1))*53+VALUE(MID(TEXT(D10,"000000000000000"),3,1))*59+VALUE(MID(TEXT(D10,"000000000000000"),2,1))*67+VALUE(MID(TEXT(D10,"000000000000000"),1,1))*71),11))=1,1,11-(MOD((VALUE(MID(TEXT(D10,"000000000000000"),15,1))*3+VALUE(MID(TEXT(D10,"000000000000000"),14,1))*7+VALUE(MID(TEXT(D10,"000000000000000"),13,1))*13+VALUE(MID(TEXT(D10,"000000000000000"),12,1))*17+VALUE(MID(TEXT(D10,"000000000000000"),11,1))*19+VALUE(MID(TEXT(D10,"000000000000000"),10,1))*23+VALUE(MID(TEXT(D10,"000000000000000"),9,1))*29+VALUE(MID(TEXT(D10,"000000000000000"),8,1))*37+VALUE(MID(TEXT(D10,"000000000000000"),7,1))*41+VALUE(MID(TEXT(D10,"000000000000000"),6,1))*43+VALUE(MID(TEXT(D10,"000000000000000"),5,1))*47+VALUE(MID(TEXT(D10,"000000000000000"),4,1))*53+VALUE(MID(TEXT(D10,"000000000000000"),3,1))*59+VALUE(MID(TEXT(D10,"000000000000000"),2,1))*67+VALUE(MID(TEXT(D10,"000000000000000"),1,1))*71),11)))) -> 2 | F10: =+AN10 -> 1950000 | G10: =+F10*$G$5 -> 370500 | H10: NO | I10: =IF(H10="S",-F10*$I$5,"NO RETENCIÓN") -> NO RETENCIÓN | J10: =+F10+G10 -> 2320500 | K10: =SUM(F10:I10) -> 2320500 | M10: GTFF-168 | N10: Correo | O10: 45987 | R10: =+AM10 -> 0 | T10: BETANCUR RESTREPO SARA LUISA | V10: SI | W10: =ROUND(IF(V10="SI",SUMIF('Facturas año anterior'!$B$8:$B$81,B10,'Facturas año anterior'!$V$8:$V$81)*(100%+$W$5),0),-3)+ROUND(IF(V10="SI",SUMIF('C de C año anterior'!$B$8:$B$210,B10,'C de C año anterior'!$Q$8:$Q$210)*(100%+$W$5),0),-3) -> 612000 | Y10: =ROUND(IF(X10="SI",W10*$Y$5,0),-3) -> 0 | Z10: si | AA10: =ROUND(IF(Z10="SI",W10*$AA$5,0),-3) -> 459000 | AC10: =ROUND(IF(AB10="SI",W10*$AC$5,0),-3) -> 0 | AE10: =ROUND(IF(AD10="SI",W10*$AE$5,0),-3) -> 0 | AG10: =ROUND(IF(AF10="SI",W10*$AG$5,0),-3) -> 0 | AI10: =ROUND(IF(AH10="SI",W10*$AI$5,0),-3) -> 0 | AJ10: SI | AK10: =IF(AJ10="SI",W10*$AK$5,0) -> 183600 | AL10: =SUMIF('Otras Asesorías y Préstamos'!$B$7:$B$242,B10,'Otras Asesorías y Préstamos'!$F$7:$F$242) -> 690501.15 | AM10: =SUMIF('Otras Asesorías y Préstamos'!$B$7:$B$242,B10,'Otras Asesorías y Préstamos'!$V$7:$V$242) -> 0 | AN10: =ROUND(SUM(W10:AL10),-4) -> 1950000
A11: =+A10+1 -> 3 | B11: CADAVID GALLEGO JULIA CRISTINA | C11: =_xlfn.XLOOKUP(B11,Códigos!$B$8:$B$406,Códigos!$A$8:$A$406,"Verificar",0) -> 59 | D11: =_xlfn.XLOOKUP(B11,'Consolidado Cobros'!$B$10:$B$312,'Consolidado Cobros'!$C$10:$C$312,"Verificar",0) -> 43255512 | E11: =IF((MOD((VALUE(MID(TEXT(D11,"000000000000000"),15,1))*3+VALUE(MID(TEXT(D11,"000000000000000"),14,1))*7+VALUE(MID(TEXT(D11,"000000000000000"),13,1))*13+VALUE(MID(TEXT(D11,"000000000000000"),12,1))*17+VALUE(MID(TEXT(D11,"000000000000000"),11,1))*19+VALUE(MID(TEXT(D11,"000000000000000"),10,1))*23+VALUE(MID(TEXT(D11,"000000000000000"),9,1))*29+VALUE(MID(TEXT(D11,"000000000000000"),8,1))*37+VALUE(MID(TEXT(D11,"000000000000000"),7,1))*41+VALUE(MID(TEXT(D11,"000000000000000"),6,1))*43+VALUE(MID(TEXT(D11,"000000000000000"),5,1))*47+VALUE(MID(TEXT(D11,"000000000000000"),4,1))*53+VALUE(MID(TEXT(D11,"000000000000000"),3,1))*59+VALUE(MID(TEXT(D11,"000000000000000"),2,1))*67+VALUE(MID(TEXT(D11,"000000000000000"),1,1))*71),11))=0,0,IF((MOD((VALUE(MID(TEXT(D11,"000000000000000"),15,1))*3+VALUE(MID(TEXT(D11,"000000000000000"),14,1))*7+VALUE(MID(TEXT(D11,"000000000000000"),13,1))*13+VALUE(MID(TEXT(D11,"000000000000000"),12,1))*17+VALUE(MID(TEXT(D11,"000000000000000"),11,1))*19+VALUE(MID(TEXT(D11,"000000000000000"),10,1))*23+VALUE(MID(TEXT(D11,"000000000000000"),9,1))*29+VALUE(MID(TEXT(D11,"000000000000000"),8,1))*37+VALUE(MID(TEXT(D11,"000000000000000"),7,1))*41+VALUE(MID(TEXT(D11,"000000000000000"),6,1))*43+VALUE(MID(TEXT(D11,"000000000000000"),5,1))*47+VALUE(MID(TEXT(D11,"000000000000000"),4,1))*53+VALUE(MID(TEXT(D11,"000000000000000"),3,1))*59+VALUE(MID(TEXT(D11,"000000000000000"),2,1))*67+VALUE(MID(TEXT(D11,"000000000000000"),1,1))*71),11))=1,1,11-(MOD((VALUE(MID(TEXT(D11,"000000000000000"),15,1))*3+VALUE(MID(TEXT(D11,"000000000000000"),14,1))*7+VALUE(MID(TEXT(D11,"000000000000000"),13,1))*13+VALUE(MID(TEXT(D11,"000000000000000"),12,1))*17+VALUE(MID(TEXT(D11,"000000000000000"),11,1))*19+VALUE(MID(TEXT(D11,"000000000000000"),10,1))*23+VALUE(MID(TEXT(D11,"000000000000000"),9,1))*29+VALUE(MID(TEXT(D11,"000000000000000"),8,1))*37+VALUE(MID(TEXT(D11,"000000000000000"),7,1))*41+VALUE(MID(TEXT(D11,"000000000000000"),6,1))*43+VALUE(MID(TEXT(D11,"000000000000000"),5,1))*47+VALUE(MID(TEXT(D11,"000000000000000"),4,1))*53+VALUE(MID(TEXT(D11,"000000000000000"),3,1))*59+VALUE(MID(TEXT(D11,"000000000000000"),2,1))*67+VALUE(MID(TEXT(D11,"000000000000000"),1,1))*71),11)))) -> 0 | F11: =+AN11 -> 610000 | G11: =+F11*$G$5 -> 115900 | H11: S | I11: =IF(H11="S",-F11*$I$5,"NO RETENCIÓN") -> -67100 | J11: =+F11+G11 -> 725900 | K11: =SUM(F11:I11) -> 658800 | M11: GTFF-175 | N11: Correo | O11: 45987 | R11: =+AM11 -> 0 | T11: Fra con -San Antonio de la Almería | V11: SI | W11: =ROUND(IF(V11="SI",SUMIF('Facturas año anterior'!$B$8:$B$81,B11,'Facturas año anterior'!$V$8:$V$81)*(100%+$W$5),0),-3)+ROUND(IF(V11="SI",SUMIF('C de C año anterior'!$B$8:$B$210,B11,'C de C año anterior'!$Q$8:$Q$210)*(100%+$W$5),0),-3) -> 612000 | Y11: =ROUND(IF(X11="SI",W11*$Y$5,0),-3) -> 0 | AA11: =ROUND(IF(Z11="SI",W11*$AA$5,0),-3) -> 0 | AC11: =ROUND(IF(AB11="SI",W11*$AC$5,0),-3) -> 0 | AE11: =ROUND(IF(AD11="SI",W11*$AE$5,0),-3) -> 0 | AG11: =ROUND(IF(AF11="SI",W11*$AG$5,0),-3) -> 0 | AI11: =ROUND(IF(AH11="SI",W11*$AI$5,0),-3) -> 0 | AK11: =IF(AJ11="SI",W11*$AK$5,0) -> 0 | AL11: =SUMIF('Otras Asesorías y Préstamos'!$B$7:$B$242,B11,'Otras Asesorías y Préstamos'!$F$7:$F$242) -> 0 | AM11: =SUMIF('Otras Asesorías y Préstamos'!$B$7:$B$242,B11,'Otras Asesorías y Préstamos'!$V$7:$V$242) -> 0 | AN11: =ROUND(SUM(W11:AL11),-4) -> 610000
A12: =+A11+1 -> 4 | B12: CORREA DE RÍOS MIRYAM DEL SOCORRO | C12: =_xlfn.XLOOKUP(B12,Códigos!$B$8:$B$406,Códigos!$A$8:$A$406,"Verificar",0) -> 75 | D12: =_xlfn.XLOOKUP(B12,'Consolidado Cobros'!$B$10:$B$312,'Consolidado Cobros'!$C$10:$C$312,"Verificar",0) -> 21829209 | E12: =IF((MOD((VALUE(MID(TEXT(D12,"000000000000000"),15,1))*3+VALUE(MID(TEXT(D12,"000000000000000"),14,1))*7+VALUE(MID(TEXT(D12,"000000000000000"),13,1))*13+VALUE(MID(TEXT(D12,"000000000000000"),12,1))*17+VALUE(MID(TEXT(D12,"000000000000000"),11,1))*19+VALUE(MID(TEXT(D12,"000000000000000"),10,1))*23+VALUE(MID(TEXT(D12,"000000000000000"),9,1))*29+VALUE(MID(TEXT(D12,"000000000000000"),8,1))*37+VALUE(MID(TEXT(D12,"000000000000000"),7,1))*41+VALUE(MID(TEXT(D12,"000000000000000"),6,1))*43+VALUE(MID(TEXT(D12,"000000000000000"),5,1))*47+VALUE(MID(TEXT(D12,"000000000000000"),4,1))*53+VALUE(MID(TEXT(D12,"000000000000000"),3,1))*59+VALUE(MID(TEXT(D12,"000000000000000"),2,1))*67+VALUE(MID(TEXT(D12,"000000000000000"),1,1))*71),11))=0,0,IF((MOD((VALUE(MID(TEXT(D12,"000000000000000"),15,1))*3+VALUE(MID(TEXT(D12,"000000000000000"),14,1))*7+VALUE(MID(TEXT(D12,"000000000000000"),13,1))*13+VALUE(MID(TEXT(D12,"000000000000000"),12,1))*17+VALUE(MID(TEXT(D12,"000000000000000"),11,1))*19+VALUE(MID(TEXT(D12,"000000000000000"),10,1))*23+VALUE(MID(TEXT(D12,"000000000000000"),9,1))*29+VALUE(MID(TEXT(D12,"000000000000000"),8,1))*37+VALUE(MID(TEXT(D12,"000000000000000"),7,1))*41+VALUE(MID(TEXT(D12,"000000000000000"),6,1))*43+VALUE(MID(TEXT(D12,"000000000000000"),5,1))*47+VALUE(MID(TEXT(D12,"000000000000000"),4,1))*53+VALUE(MID(TEXT(D12,"000000000000000"),3,1))*59+VALUE(MID(TEXT(D12,"000000000000000"),2,1))*67+VALUE(MID(TEXT(D12,"000000000000000"),1,1))*71),11))=1,1,11-(MOD((VALUE(MID(TEXT(D12,"000000000000000"),15,1))*3+VALUE(MID(TEXT(D12,"000000000000000"),14,1))*7+VALUE(MID(TEXT(D12,"000000000000000"),13,1))*13+VALUE(MID(TEXT(D12,"000000000000000"),12,1))*17+VALUE(MID(TEXT(D12,"000000000000000"),11,1))*19+VALUE(MID(TEXT(D12,"000000000000000"),10,1))*23+VALUE(MID(TEXT(D12,"000000000000000"),9,1))*29+VALUE(MID(TEXT(D12,"000000000000000"),8,1))*37+VALUE(MID(TEXT(D12,"000000000000000"),7,1))*41+VALUE(MID(TEXT(D12,"000000000000000"),6,1))*43+VALUE(MID(TEXT(D12,"000000000000000"),5,1))*47+VALUE(MID(TEXT(D12,"000000000000000"),4,1))*53+VALUE(MID(TEXT(D12,"000000000000000"),3,1))*59+VALUE(MID(TEXT(D12,"000000000000000"),2,1))*67+VALUE(MID(TEXT(D12,"000000000000000"),1,1))*71),11)))) -> 8 | F12: =+AN12 -> 2240000 | G12: =+F12*$G$5 -> 425600 | H12: S | I12: =IF(H12="S",-F12*$I$5,"NO RETENCIÓN") -> -246400 | J12: =+F12+G12 -> 2665600 | K12: =SUM(F12:I12) -> 2419200 | N12: ES CXC | R12: =+AM12 -> 0 | T12: Se hace cuenta de cobro | V12: SI | W12: =ROUND(IF(V12="SI",SUMIF('Facturas año anterior'!$B$8:$B$81,B12,'Facturas año anterior'!$V$8:$V$81)*(100%+$W$5),0),-3)+ROUND(IF(V12="SI",SUMIF('C de C año anterior'!$B$8:$B$210,B12,'C de C año anterior'!$Q$8:$Q$210)*(100%+$W$5),0),-3) -> 994000 | X12: SI | Y12: =ROUND(IF(X12="SI",W12*$Y$5,0),-3) -> 497000 | Z12: SI | AA12: =ROUND(IF(Z12="SI",W12*$AA$5,0),-3) -> 746000 | AC12: =ROUND(IF(AB12="SI",W12*$AC$5,0),-3) -> 0 | AE12: =ROUND(IF(AD12="SI",W12*$AE$5,0),-3) -> 0 | AG12: =ROUND(IF(AF12="SI",W12*$AG$5,0),-3) -> 0 | AI12: =ROUND(IF(AH12="SI",W12*$AI$5,0),-3) -> 0 | AK12: =IF(AJ12="SI",W12*$AK$5,0) -> 0 | AL12: =SUMIF('Otras Asesorías y Préstamos'!$B$7:$B$242,B12,'Otras Asesorías y Préstamos'!$F$7:$F$242) -> 0 | AM12: =SUMIF('Otras Asesorías y Préstamos'!$B$7:$B$242,B12,'Otras Asesorías y Préstamos'!$V$7:$V$242) -> 0 | AN12: =ROUND(SUM(W12:AL12),-4) -> 2240000
A13: =+A12+1 -> 5 | B13: ECHAVARRÍA DE VILLEGAS ANA ISABEL | C13: =_xlfn.XLOOKUP(B13,Códigos!$B$8:$B$406,Códigos!$A$8:$A$406,"Verificar",0) -> 81 | D13: =_xlfn.XLOOKUP(B13,'Consolidado Cobros'!$B$10:$B$312,'Consolidado Cobros'!$C$10:$C$312,"Verificar",0) -> 21378780 | E13: =IF((MOD((VALUE(MID(TEXT(D13,"000000000000000"),15,1))*3+VALUE(MID(TEXT(D13,"000000000000000"),14,1))*7+VALUE(MID(TEXT(D13,"000000000000000"),13,1))*13+VALUE(MID(TEXT(D13,"000000000000000"),12,1))*17+VALUE(MID(TEXT(D13,"000000000000000"),11,1))*19+VALUE(MID(TEXT(D13,"000000000000000"),10,1))*23+VALUE(MID(TEXT(D13,"000000000000000"),9,1))*29+VALUE(MID(TEXT(D13,"000000000000000"),8,1))*37+VALUE(MID(TEXT(D13,"000000000000000"),7,1))*41+VALUE(MID(TEXT(D13,"000000000000000"),6,1))*43+VALUE(MID(TEXT(D13,"000000000000000"),5,1))*47+VALUE(MID(TEXT(D13,"000000000000000"),4,1))*53+VALUE(MID(TEXT(D13,"000000000000000"),3,1))*59+VALUE(MID(TEXT(D13,"000000000000000"),2,1))*67+VALUE(MID(TEXT(D13,"000000000000000"),1,1))*71),11))=0,0,IF((MOD((VALUE(MID(TEXT(D13,"000000000000000"),15,1))*3+VALUE(MID(TEXT(D13,"000000000000000"),14,1))*7+VALUE(MID(TEXT(D13,"000000000000000"),13,1))*13+VALUE(MID(TEXT(D13,"000000000000000"),12,1))*17+VALUE(MID(TEXT(D13,"000000000000000"),11,1))*19+VALUE(MID(TEXT(D13,"000000000000000"),10,1))*23+VALUE(MID(TEXT(D13,"000000000000000"),9,1))*29+VALUE(MID(TEXT(D13,"000000000000000"),8,1))*37+VALUE(MID(TEXT(D13,"000000000000000"),7,1))*41+VALUE(MID(TEXT(D13,"000000000000000"),6,1))*43+VALUE(MID(TEXT(D13,"000000000000000"),5,1))*47+VALUE(MID(TEXT(D13,"000000000000000"),4,1))*53+VALUE(MID(TEXT(D13,"000000000000000"),3,1))*59+VALUE(MID(TEXT(D13,"000000000000000"),2,1))*67+VALUE(MID(TEXT(D13,"000000000000000"),1,1))*71),11))=1,1,11-(MOD((VALUE(MID(TEXT(D13,"000000000000000"),15,1))*3+VALUE(MID(TEXT(D13,"000000000000000"),14,1))*7+VALUE(MID(TEXT(D13,"000000000000000"),13,1))*13+VALUE(MID(TEXT(D13,"000000000000000"),12,1))*17+VALUE(MID(TEXT(D13,"000000000000000"),11,1))*19+VALUE(MID(TEXT(D13,"000000000000000"),10,1))*23+VALUE(MID(TEXT(D13,"000000000000000"),9,1))*29+VALUE(MID(TEXT(D13,"000000000000000"),8,1))*37+VALUE(MID(TEXT(D13,"000000000000000"),7,1))*41+VALUE(MID(TEXT(D13,"000000000000000"),6,1))*43+VALUE(MID(TEXT(D13,"000000000000000"),5,1))*47+VALUE(MID(TEXT(D13,"000000000000000"),4,1))*53+VALUE(MID(TEXT(D13,"000000000000000"),3,1))*59+VALUE(MID(TEXT(D13,"000000000000000"),2,1))*67+VALUE(MID(TEXT(D13,"000000000000000"),1,1))*71),11)))) -> 6 | F13: =+AN13 -> 1900000 | G13: =+F13*$G$5 -> 361000 | H13: S | I13: =IF(H13="S",-F13*$I$5,"NO RETENCIÓN") -> -209000 | J13: =+F13+G13 -> 2261000 | K13: =SUM(F13:I13) -> 2052000 | M13: GTFF-184 | N13: Correo | O13: 45987 | R13: =+AM13 -> 0 | T13: Fra con -Truly Nolen | V13: SI | W13: =ROUND(IF(V13="SI",SUMIF('Facturas año anterior'!$B$8:$B$81,B13,'Facturas año anterior'!$V$8:$V$81)*(100%+$W$5),0),-3)+ROUND(IF(V13="SI",SUMIF('C de C año anterior'!$B$8:$B$210,B13,'C de C año anterior'!$Q$8:$Q$210)*(100%+$W$5),0),-3) -> 1904000 | Y13: =ROUND(IF(X13="SI",W13*$Y$5,0),-3) -> 0 | AA13: =ROUND(IF(Z13="SI",W13*$AA$5,0),-3) -> 0 | AC13: =ROUND(IF(AB13="SI",W13*$AC$5,0),-3) -> 0 | AE13: =ROUND(IF(AD13="SI",W13*$AE$5,0),-3) -> 0 | AG13: =ROUND(IF(AF13="SI",W13*$AG$5,0),-3) -> 0 | AI13: =ROUND(IF(AH13="SI",W13*$AI$5,0),-3) -> 0 | AK13: =IF(AJ13="SI",W13*$AK$5,0) -> 0 | AL13: =SUMIF('Otras Asesorías y Préstamos'!$B$7:$B$242,B13,'Otras Asesorías y Préstamos'!$F$7:$F$242) -> 0 | AM13: =SUMIF('Otras Asesorías y Préstamos'!$B$7:$B$242,B13,'Otras Asesorías y Préstamos'!$V$7:$V$242) -> 0 | AN13: =ROUND(SUM(W13:AL13),-4) -> 1900000
A14: =+A13+1 -> 6 | B14: GALLEGO ARIAS GLORIA CRISTINA | C14: =_xlfn.XLOOKUP(B14,Códigos!$B$8:$B$406,Códigos!$A$8:$A$406,"Verificar",0) -> 54 | D14: =_xlfn.XLOOKUP(B14,'Consolidado Cobros'!$B$10:$B$312,'Consolidado Cobros'!$C$10:$C$312,"Verificar",0) -> 43422834 | E14: =IF((MOD((VALUE(MID(TEXT(D14,"000000000000000"),15,1))*3+VALUE(MID(TEXT(D14,"000000000000000"),14,1))*7+VALUE(MID(TEXT(D14,"000000000000000"),13,1))*13+VALUE(MID(TEXT(D14,"000000000000000"),12,1))*17+VALUE(MID(TEXT(D14,"000000000000000"),11,1))*19+VALUE(MID(TEXT(D14,"000000000000000"),10,1))*23+VALUE(MID(TEXT(D14,"000000000000000"),9,1))*29+VALUE(MID(TEXT(D14,"000000000000000"),8,1))*37+VALUE(MID(TEXT(D14,"000000000000000"),7,1))*41+VALUE(MID(TEXT(D14,"000000000000000"),6,1))*43+VALUE(MID(TEXT(D14,"000000000000000"),5,1))*47+VALUE(MID(TEXT(D14,"000000000000000"),4,1))*53+VALUE(MID(TEXT(D14,"000000000000000"),3,1))*59+VALUE(MID(TEXT(D14,"000000000000000"),2,1))*67+VALUE(MID(TEXT(D14,"000000000000000"),1,1))*71),11))=0,0,IF((MOD((VALUE(MID(TEXT(D14,"000000000000000"),15,1))*3+VALUE(MID(TEXT(D14,"000000000000000"),14,1))*7+VALUE(MID(TEXT(D14,"000000000000000"),13,1))*13+VALUE(MID(TEXT(D14,"000000000000000"),12,1))*17+VALUE(MID(TEXT(D14,"000000000000000"),11,1))*19+VALUE(MID(TEXT(D14,"000000000000000"),10,1))*23+VALUE(MID(TEXT(D14,"000000000000000"),9,1))*29+VALUE(MID(TEXT(D14,"000000000000000"),8,1))*37+VALUE(MID(TEXT(D14,"000000000000000"),7,1))*41+VALUE(MID(TEXT(D14,"000000000000000"),6,1))*43+VALUE(MID(TEXT(D14,"000000000000000"),5,1))*47+VALUE(MID(TEXT(D14,"000000000000000"),4,1))*53+VALUE(MID(TEXT(D14,"000000000000000"),3,1))*59+VALUE(MID(TEXT(D14,"000000000000000"),2,1))*67+VALUE(MID(TEXT(D14,"000000000000000"),1,1))*71),11))=1,1,11-(MOD((VALUE(MID(TEXT(D14,"000000000000000"),15,1))*3+VALUE(MID(TEXT(D14,"000000000000000"),14,1))*7+VALUE(MID(TEXT(D14,"000000000000000"),13,1))*13+VALUE(MID(TEXT(D14,"000000000000000"),12,1))*17+VALUE(MID(TEXT(D14,"000000000000000"),11,1))*19+VALUE(MID(TEXT(D14,"000000000000000"),10,1))*23+VALUE(MID(TEXT(D14,"000000000000000"),9,1))*29+VALUE(MID(TEXT(D14,"000000000000000"),8,1))*37+VALUE(MID(TEXT(D14,"000000000000000"),7,1))*41+VALUE(MID(TEXT(D14,"000000000000000"),6,1))*43+VALUE(MID(TEXT(D14,"000000000000000"),5,1))*47+VALUE(MID(TEXT(D14,"000000000000000"),4,1))*53+VALUE(MID(TEXT(D14,"000000000000000"),3,1))*59+VALUE(MID(TEXT(D14,"000000000000000"),2,1))*67+VALUE(MID(TEXT(D14,"000000000000000"),1,1))*71),11)))) -> 3 | F14: =+AN14 -> 610000 | G14: =+F14*$G$5 -> 115900 | H14: S | I14: =IF(H14="S",-F14*$I$5,"NO RETENCIÓN") -> -67100 | J14: =+F14+G14 -> 725900 | K14: =SUM(F14:I14) -> 658800 | M14: GTFF-175 | N14: Correo | O14: 45987 | R14: =+AM14 -> 0 | T14: Fra con -San Antonio de la Almería | V14: SI | W14: =ROUND(IF(V14="SI",SUMIF('Facturas año anterior'!$B$8:$B$81,B14,'Facturas año anterior'!$V$8:$V$81)*(100%+$W$5),0),-3)+ROUND(IF(V14="SI",SUMIF('C de C año anterior'!$B$8:$B$210,B14,'C de C año anterior'!$Q$8:$Q$210)*(100%+$W$5),0),-3) -> 612000 | Y14: =ROUND(IF(X14="SI",W14*$Y$5,0),-3) -> 0 | AA14: =ROUND(IF(Z14="SI",W14*$AA$5,0),-3) -> 0 | AC14: =ROUND(IF(AB14="SI",W14*$AC$5,0),-3) -> 0 | AE14: =ROUND(IF(AD14="SI",W14*$AE$5,0),-3) -> 0 | AG14: =ROUND(IF(AF14="SI",W14*$AG$5,0),-3) -> 0 | AI14: =ROUND(IF(AH14="SI",W14*$AI$5,0),-3) -> 0 | AK14: =IF(AJ14="SI",W14*$AK$5,0) -> 0 | AL14: =SUMIF('Otras Asesorías y Préstamos'!$B$7:$B$242,B14,'Otras Asesorías y Préstamos'!$F$7:$F$242) -> 0 | AM14: =SUMIF('Otras Asesorías y Préstamos'!$B$7:$B$242,B14,'Otras Asesorías y Préstamos'!$V$7:$V$242) -> 0 | AN14: =ROUND(SUM(W14:AL14),-4) -> 610000
A15: =+A14+1 -> 7 | B15: GALLEGO ARIAS MIRIAM DEL SOCORRO | C15: =_xlfn.XLOOKUP(B15,Códigos!$B$8:$B$406,Códigos!$A$8:$A$406,"Verificar",0) -> 99 | D15: =_xlfn.XLOOKUP(B15,'Consolidado Cobros'!$B$10:$B$312,'Consolidado Cobros'!$C$10:$C$312,"Verificar",0) -> 43422711 | E15: =IF((MOD((VALUE(MID(TEXT(D15,"000000000000000"),15,1))*3+VALUE(MID(TEXT(D15,"000000000000000"),14,1))*7+VALUE(MID(TEXT(D15,"000000000000000"),13,1))*13+VALUE(MID(TEXT(D15,"000000000000000"),12,1))*17+VALUE(MID(TEXT(D15,"000000000000000"),11,1))*19+VALUE(MID(TEXT(D15,"000000000000000"),10,1))*23+VALUE(MID(TEXT(D15,"000000000000000"),9,1))*29+VALUE(MID(TEXT(D15,"000000000000000"),8,1))*37+VALUE(MID(TEXT(D15,"000000000000000"),7,1))*41+VALUE(MID(TEXT(D15,"000000000000000"),6,1))*43+VALUE(MID(TEXT(D15,"000000000000000"),5,1))*47+VALUE(MID(TEXT(D15,"000000000000000"),4,1))*53+VALUE(MID(TEXT(D15,"000000000000000"),3,1))*59+VALUE(MID(TEXT(D15,"000000000000000"),2,1))*67+VALUE(MID(TEXT(D15,"000000000000000"),1,1))*71),11))=0,0,IF((MOD((VALUE(MID(TEXT(D15,"000000000000000"),15,1))*3+VALUE(MID(TEXT(D15,"000000000000000"),14,1))*7+VALUE(MID(TEXT(D15,"000000000000000"),13,1))*13+VALUE(MID(TEXT(D15,"000000000000000"),12,1))*17+VALUE(MID(TEXT(D15,"000000000000000"),11,1))*19+VALUE(MID(TEXT(D15,"000000000000000"),10,1))*23+VALUE(MID(TEXT(D15,"000000000000000"),9,1))*29+VALUE(MID(TEXT(D15,"000000000000000"),8,1))*37+VALUE(MID(TEXT(D15,"000000000000000"),7,1))*41+VALUE(MID(TEXT(D15,"000000000000000"),6,1))*43+VALUE(MID(TEXT(D15,"000000000000000"),5,1))*47+VALUE(MID(TEXT(D15,"000000000000000"),4,1))*53+VALUE(MID(TEXT(D15,"000000000000000"),3,1))*59+VALUE(MID(TEXT(D15,"000000000000000"),2,1))*67+VALUE(MID(TEXT(D15,"000000000000000"),1,1))*71),11))=1,1,11-(MOD((VALUE(MID(TEXT(D15,"000000000000000"),15,1))*3+VALUE(MID(TEXT(D15,"000000000000000"),14,1))*7+VALUE(MID(TEXT(D15,"000000000000000"),13,1))*13+VALUE(MID(TEXT(D15,"000000000000000"),12,1))*17+VALUE(MID(TEXT(D15,"000000000000000"),11,1))*19+VALUE(MID(TEXT(D15,"000000000000000"),10,1))*23+VALUE(MID(TEXT(D15,"000000000000000"),9,1))*29+VALUE(MID(TEXT(D15,"000000000000000"),8,1))*37+VALUE(MID(TEXT(D15,"000000000000000"),7,1))*41+VALUE(MID(TEXT(D15,"000000000000000"),6,1))*43+VALUE(MID(TEXT(D15,"000000000000000"),5,1))*47+VALUE(MID(TEXT(D15,"000000000000000"),4,1))*53+VALUE(MID(TEXT(D15,"000000000000000"),3,1))*59+VALUE(MID(TEXT(D15,"000000000000000"),2,1))*67+VALUE(MID(TEXT(D15,"000000000000000"),1,1))*71),11)))) -> 6 | F15: =+AN15 -> 1410000 | G15: =+F15*$G$5 -> 267900 | H15: S | I15: =IF(H15="S",-F15*$I$5,"NO RETENCIÓN") -> -155100 | J15: =+F15+G15 -> 1677900 | K15: =SUM(F15:I15) -> 1522800 | M15: GTFF-175 | N15: Correo | O15: 45987 | R15: =+AM15 -> 0 | T15: Fra con -San Antonio de la Almería | V15: SI | W15: =ROUND(IF(V15="SI",SUMIF('Facturas año anterior'!$B$8:$B$81,B15,'Facturas año anterior'!$V$8:$V$81)*(100%+$W$5),0),-3)+ROUND(IF(V15="SI",SUMIF('C de C año anterior'!$B$8:$B$210,B15,'C de C año anterior'!$Q$8:$Q$210)*(100%+$W$5),0),-3) -> 1410000 | Y15: =ROUND(IF(X15="SI",W15*$Y$5,0),-3) -> 0 | AA15: =ROUND(IF(Z15="SI",W15*$AA$5,0),-3) -> 0 | AC15: =ROUND(IF(AB15="SI",W15*$AC$5,0),-3) -> 0 | AE15: =ROUND(IF(AD15="SI",W15*$AE$5,0),-3) -> 0 | AG15: =ROUND(IF(AF15="SI",W15*$AG$5,0),-3) -> 0 | AI15: =ROUND(IF(AH15="SI",W15*$AI$5,0),-3) -> 0 | AK15: =IF(AJ15="SI",W15*$AK$5,0) -> 0 | AL15: =SUMIF('Otras Asesorías y Préstamos'!$B$7:$B$242,B15,'Otras Asesorías y Préstamos'!$F$7:$F$242) -> 0 | AM15: =SUMIF('Otras Asesorías y Préstamos'!$B$7:$B$242,B15,'Otras Asesorías y Préstamos'!$V$7:$V$242) -> 0 | AN15: =ROUND(SUM(W15:AL15),-4) -> 1410000
A16: =+A15+1 -> 8 | B16: MAYA JIMÉNEZ MARÍA TERESA | C16: =_xlfn.XLOOKUP(B16,Códigos!$B$8:$B$406,Códigos!$A$8:$A$406,"Verificar",0) -> 80 | D16: =_xlfn.XLOOKUP(B16,'Consolidado Cobros'!$B$10:$B$312,'Consolidado Cobros'!$C$10:$C$312,"Verificar",0) -> 1037630601 | E16: =IF((MOD((VALUE(MID(TEXT(D16,"000000000000000"),15,1))*3+VALUE(MID(TEXT(D16,"000000000000000"),14,1))*7+VALUE(MID(TEXT(D16,"000000000000000"),13,1))*13+VALUE(MID(TEXT(D16,"000000000000000"),12,1))*17+VALUE(MID(TEXT(D16,"000000000000000"),11,1))*19+VALUE(MID(TEXT(D16,"000000000000000"),10,1))*23+VALUE(MID(TEXT(D16,"000000000000000"),9,1))*29+VALUE(MID(TEXT(D16,"000000000000000"),8,1))*37+VALUE(MID(TEXT(D16,"000000000000000"),7,1))*41+VALUE(MID(TEXT(D16,"000000000000000"),6,1))*43+VALUE(MID(TEXT(D16,"000000000000000"),5,1))*47+VALUE(MID(TEXT(D16,"000000000000000"),4,1))*53+VALUE(MID(TEXT(D16,"000000000000000"),3,1))*59+VALUE(MID(TEXT(D16,"000000000000000"),2,1))*67+VALUE(MID(TEXT(D16,"000000000000000"),1,1))*71),11))=0,0,IF((MOD((VALUE(MID(TEXT(D16,"000000000000000"),15,1))*3+VALUE(MID(TEXT(D16,"000000000000000"),14,1))*7+VALUE(MID(TEXT(D16,"000000000000000"),13,1))*13+VALUE(MID(TEXT(D16,"000000000000000"),12,1))*17+VALUE(MID(TEXT(D16,"000000000000000"),11,1))*19+VALUE(MID(TEXT(D16,"000000000000000"),10,1))*23+VALUE(MID(TEXT(D16,"000000000000000"),9,1))*29+VALUE(MID(TEXT(D16,"000000000000000"),8,1))*37+VALUE(MID(TEXT(D16,"000000000000000"),7,1))*41+VALUE(MID(TEXT(D16,"000000000000000"),6,1))*43+VALUE(MID(TEXT(D16,"000000000000000"),5,1))*47+VALUE(MID(TEXT(D16,"000000000000000"),4,1))*53+VALUE(MID(TEXT(D16,"000000000000000"),3,1))*59+VALUE(MID(TEXT(D16,"000000000000000"),2,1))*67+VALUE(MID(TEXT(D16,"000000000000000"),1,1))*71),11))=1,1,11-(MOD((VALUE(MID(TEXT(D16,"000000000000000"),15,1))*3+VALUE(MID(TEXT(D16,"000000000000000"),14,1))*7+VALUE(MID(TEXT(D16,"000000000000000"),13,1))*13+VALUE(MID(TEXT(D16,"000000000000000"),12,1))*17+VALUE(MID(TEXT(D16,"000000000000000"),11,1))*19+VALUE(MID(TEXT(D16,"000000000000000"),10,1))*23+VALUE(MID(TEXT(D16,"000000000000000"),9,1))*29+VALUE(MID(TEXT(D16,"000000000000000"),8,1))*37+VALUE(MID(TEXT(D16,"000000000000000"),7,1))*41+VALUE(MID(TEXT(D16,"000000000000000"),6,1))*43+VALUE(MID(TEXT(D16,"000000000000000"),5,1))*47+VALUE(MID(TEXT(D16,"000000000000000"),4,1))*53+VALUE(MID(TEXT(D16,"000000000000000"),3,1))*59+VALUE(MID(TEXT(D16,"000000000000000"),2,1))*67+VALUE(MID(TEXT(D16,"000000000000000"),1,1))*71),11)))) -> 5 | F16: =+AN16 -> 220000 | G16: =+F16*$G$5 -> 41800 | H16: S | I16: =IF(H16="S",-F16*$I$5,"NO RETENCIÓN") -> -24200 | J16: =+F16+G16 -> 261800 | K16: =SUM(F16:I16) -> 237600 | M16: GTFF-187 | N16: Correo | O16: 45987 | R16: =+AM16 -> 0 | T16: Fra con -Ruiz González Álvaro H. | V16: SI | W16: =ROUND(IF(V16="SI",SUMIF('Facturas año anterior'!$B$8:$B$81,B16,'Facturas año anterior'!$V$8:$V$81)*(100%+$W$5),0),-3)+ROUND(IF(V16="SI",SUMIF('C de C año anterior'!$B$8:$B$210,B16,'C de C año anterior'!$Q$8:$Q$210)*(100%+$W$5),0),-3) -> 221000 | Y16: =ROUND(IF(X16="SI",W16*$Y$5,0),-3) -> 0 | AA16: =ROUND(IF(Z16="SI",W16*$AA$5,0),-3) -> 0 | AC16: =ROUND(IF(AB16="SI",W16*$AC$5,0),-3) -> 0 | AE16: =ROUND(IF(AD16="SI",W16*$AE$5,0),-3) -> 0 | AG16: =ROUND(IF(AF16="SI",W16*$AG$5,0),-3) -> 0 | AI16: =ROUND(IF(AH16="SI",W16*$AI$5,0),-3) -> 0 | AK16: =IF(AJ16="SI",W16*$AK$5,0) -> 0 | AL16: =SUMIF('Otras Asesorías y Préstamos'!$B$7:$B$242,B16,'Otras Asesorías y Préstamos'!$F$7:$F$242) -> 0 | AM16: =SUMIF('Otras Asesorías y Préstamos'!$B$7:$B$242,B16,'Otras Asesorías y Préstamos'!$V$7:$V$242) -> 0 | AN16: =ROUND(SUM(W16:AL16),-4) -> 220000
A17: =+A16+1 -> 9 | B17: MEJÍA DUQUE LINA MARÍA | C17: =_xlfn.XLOOKUP(B17,Códigos!$B$8:$B$406,Códigos!$A$8:$A$406,"Verificar",0) -> 216 | D17: =_xlfn.XLOOKUP(B17,'Consolidado Cobros'!$B$10:$B$312,'Consolidado Cobros'!$C$10:$C$312,"Verificar",0) -> 32523581 | E17: =IF((MOD((VALUE(MID(TEXT(D17,"000000000000000"),15,1))*3+VALUE(MID(TEXT(D17,"000000000000000"),14,1))*7+VALUE(MID(TEXT(D17,"000000000000000"),13,1))*13+VALUE(MID(TEXT(D17,"000000000000000"),12,1))*17+VALUE(MID(TEXT(D17,"000000000000000"),11,1))*19+VALUE(MID(TEXT(D17,"000000000000000"),10,1))*23+VALUE(MID(TEXT(D17,"000000000000000"),9,1))*29+VALUE(MID(TEXT(D17,"000000000000000"),8,1))*37+VALUE(MID(TEXT(D17,"000000000000000"),7,1))*41+VALUE(MID(TEXT(D17,"000000000000000"),6,1))*43+VALUE(MID(TEXT(D17,"000000000000000"),5,1))*47+VALUE(MID(TEXT(D17,"000000000000000"),4,1))*53+VALUE(MID(TEXT(D17,"000000000000000"),3,1))*59+VALUE(MID(TEXT(D17,"000000000000000"),2,1))*67+VALUE(MID(TEXT(D17,"000000000000000"),1,1))*71),11))=0,0,IF((MOD((VALUE(MID(TEXT(D17,"000000000000000"),15,1))*3+VALUE(MID(TEXT(D17,"000000000000000"),14,1))*7+VALUE(MID(TEXT(D17,"000000000000000"),13,1))*13+VALUE(MID(TEXT(D17,"000000000000000"),12,1))*17+VALUE(MID(TEXT(D17,"000000000000000"),11,1))*19+VALUE(MID(TEXT(D17,"000000000000000"),10,1))*23+VALUE(MID(TEXT(D17,"000000000000000"),9,1))*29+VALUE(MID(TEXT(D17,"000000000000000"),8,1))*37+VALUE(MID(TEXT(D17,"000000000000000"),7,1))*41+VALUE(MID(TEXT(D17,"000000000000000"),6,1))*43+VALUE(MID(TEXT(D17,"000000000000000"),5,1))*47+VALUE(MID(TEXT(D17,"000000000000000"),4,1))*53+VALUE(MID(TEXT(D17,"000000000000000"),3,1))*59+VALUE(MID(TEXT(D17,"000000000000000"),2,1))*67+VALUE(MID(TEXT(D17,"000000000000000"),1,1))*71),11))=1,1,11-(MOD((VALUE(MID(TEXT(D17,"000000000000000"),15,1))*3+VALUE(MID(TEXT(D17,"000000000000000"),14,1))*7+VALUE(MID(TEXT(D17,"000000000000000"),13,1))*13+VALUE(MID(TEXT(D17,"000000000000000"),12,1))*17+VALUE(MID(TEXT(D17,"000000000000000"),11,1))*19+VALUE(MID(TEXT(D17,"000000000000000"),10,1))*23+VALUE(MID(TEXT(D17,"000000000000000"),9,1))*29+VALUE(MID(TEXT(D17,"000000000000000"),8,1))*37+VALUE(MID(TEXT(D17,"000000000000000"),7,1))*41+VALUE(MID(TEXT(D17,"000000000000000"),6,1))*43+VALUE(MID(TEXT(D17,"000000000000000"),5,1))*47+VALUE(MID(TEXT(D17,"000000000000000"),4,1))*53+VALUE(MID(TEXT(D17,"000000000000000"),3,1))*59+VALUE(MID(TEXT(D17,"000000000000000"),2,1))*67+VALUE(MID(TEXT(D17,"000000000000000"),1,1))*71),11)))) -> 9 | F17: =+AN17 -> 1480000 | G17: =+F17*$G$5 -> 281200 | H17: S | I17: =IF(H17="S",-F17*$I$5,"NO RETENCIÓN") -> -162800 | J17: =+F17+G17 -> 1761200 | K17: =SUM(F17:I17) -> 1598400 | M17: GTFF-182 | N17: Correo | O17: 45987 | R17: =+AM17 -> 0 | T17: Fra con -LINABI | V17: SI | W17: =ROUND(IF(V17="SI",SUMIF('Facturas año anterior'!$B$8:$B$81,B17,'Facturas año anterior'!$V$8:$V$81)*(100%+$W$5),0),-3)+ROUND(IF(V17="SI",SUMIF('C de C año anterior'!$B$8:$B$210,B17,'C de C año anterior'!$Q$8:$Q$210)*(100%+$W$5),0),-3) -> 1483000 | Y17: =ROUND(IF(X17="SI",W17*$Y$5,0),-3) -> 0 | AA17: =ROUND(IF(Z17="SI",W17*$AA$5,0),-3) -> 0 | AC17: =ROUND(IF(AB17="SI",W17*$AC$5,0),-3) -> 0 | AE17: =ROUND(IF(AD17="SI",W17*$AE$5,0),-3) -> 0 | AG17: =ROUND(IF(AF17="SI",W17*$AG$5,0),-3) -> 0 | AI17: =ROUND(IF(AH17="SI",W17*$AI$5,0),-3) -> 0 | AK17: =IF(AJ17="SI",W17*$AK$5,0) -> 0 | AL17: =SUMIF('Otras Asesorías y Préstamos'!$B$7:$B$242,B17,'Otras Asesorías y Préstamos'!$F$7:$F$242) -> 0 | AM17: =SUMIF('Otras Asesorías y Préstamos'!$B$7:$B$242,B17,'Otras Asesorías y Préstamos'!$V$7:$V$242) -> 0 | AN17: =ROUND(SUM(W17:AL17),-4) -> 1480000
A18: =+A17+1 -> 10 | B18: RESTREPO ÁLVAREZ LUÍS EMILIO | C18: =_xlfn.XLOOKUP(B18,Códigos!$B$8:$B$406,Códigos!$A$8:$A$406,"Verificar",0) -> 155 | D18: =_xlfn.XLOOKUP(B18,'Consolidado Cobros'!$B$10:$B$312,'Consolidado Cobros'!$C$10:$C$312,"Verificar",0) -> 92102300043 | E18: =IF((MOD((VALUE(MID(TEXT(D18,"000000000000000"),15,1))*3+VALUE(MID(TEXT(D18,"000000000000000"),14,1))*7+VALUE(MID(TEXT(D18,"000000000000000"),13,1))*13+VALUE(MID(TEXT(D18,"000000000000000"),12,1))*17+VALUE(MID(TEXT(D18,"000000000000000"),11,1))*19+VALUE(MID(TEXT(D18,"000000000000000"),10,1))*23+VALUE(MID(TEXT(D18,"000000000000000"),9,1))*29+VALUE(MID(TEXT(D18,"000000000000000"),8,1))*37+VALUE(MID(TEXT(D18,"000000000000000"),7,1))*41+VALUE(MID(TEXT(D18,"000000000000000"),6,1))*43+VALUE(MID(TEXT(D18,"000000000000000"),5,1))*47+VALUE(MID(TEXT(D18,"000000000000000"),4,1))*53+VALUE(MID(TEXT(D18,"000000000000000"),3,1))*59+VALUE(MID(TEXT(D18,"000000000000000"),2,1))*67+VALUE(MID(TEXT(D18,"000000000000000"),1,1))*71),11))=0,0,IF((MOD((VALUE(MID(TEXT(D18,"000000000000000"),15,1))*3+VALUE(MID(TEXT(D18,"000000000000000"),14,1))*7+VALUE(MID(TEXT(D18,"000000000000000"),13,1))*13+VALUE(MID(TEXT(D18,"000000000000000"),12,1))*17+VALUE(MID(TEXT(D18,"000000000000000"),11,1))*19+VALUE(MID(TEXT(D18,"000000000000000"),10,1))*23+VALUE(MID(TEXT(D18,"000000000000000"),9,1))*29+VALUE(MID(TEXT(D18,"000000000000000"),8,1))*37+VALUE(MID(TEXT(D18,"000000000000000"),7,1))*41+VALUE(MID(TEXT(D18,"000000000000000"),6,1))*43+VALUE(MID(TEXT(D18,"000000000000000"),5,1))*47+VALUE(MID(TEXT(D18,"000000000000000"),4,1))*53+VALUE(MID(TEXT(D18,"000000000000000"),3,1))*59+VALUE(MID(TEXT(D18,"000000000000000"),2,1))*67+VALUE(MID(TEXT(D18,"000000000000000"),1,1))*71),11))=1,1,11-(MOD((VALUE(MID(TEXT(D18,"000000000000000"),15,1))*3+VALUE(MID(TEXT(D18,"000000000000000"),14,1))*7+VALUE(MID(TEXT(D18,"000000000000000"),13,1))*13+VALUE(MID(TEXT(D18,"000000000000000"),12,1))*17+VALUE(MID(TEXT(D18,"000000000000000"),11,1))*19+VALUE(MID(TEXT(D18,"000000000000000"),10,1))*23+VALUE(MID(TEXT(D18,"000000000000000"),9,1))*29+VALUE(MID(TEXT(D18,"000000000000000"),8,1))*37+VALUE(MID(TEXT(D18,"000000000000000"),7,1))*41+VALUE(MID(TEXT(D18,"000000000000000"),6,1))*43+VALUE(MID(TEXT(D18,"000000000000000"),5,1))*47+VALUE(MID(TEXT(D18,"000000000000000"),4,1))*53+VALUE(MID(TEXT(D18,"000000000000000"),3,1))*59+VALUE(MID(TEXT(D18,"000000000000000"),2,1))*67+VALUE(MID(TEXT(D18,"000000000000000"),1,1))*71),11)))) -> 1 | F18: =+AN18 -> 800000 | G18: =+F18*$G$5 -> 152000 | H18: S | I18: =IF(H18="S",-F18*$I$5,"NO RETENCIÓN") -> -88000 | J18: =+F18+G18 -> 952000 | K18: =SUM(F18:I18) -> 864000 | M18: GTFF-172 | N18: Correo | O18: 45987 | R18: =+AM18 -> 0 | T18: Fra con -Invers. Luís Emilio | V18: SI | W18: =ROUND(IF(V18="SI",SUMIF('Facturas año anterior'!$B$8:$B$81,B18,'Facturas año anterior'!$V$8:$V$81)*(100%+$W$5),0),-3)+ROUND(IF(V18="SI",SUMIF('C de C año anterior'!$B$8:$B$210,B18,'C de C año anterior'!$Q$8:$Q$210)*(100%+$W$5),0),-3) -> 612000 | Y18: =ROUND(IF(X18="SI",W18*$Y$5,0),-3) -> 0 | AA18: =ROUND(IF(Z18="SI",W18*$AA$5,0),-3) -> 0 | AC18: =ROUND(IF(AB18="SI",W18*$AC$5,0),-3) -> 0 | AE18: =ROUND(IF(AD18="SI",W18*$AE$5,0),-3) -> 0 | AG18: =ROUND(IF(AF18="SI",W18*$AG$5,0),-3) -> 0 | AI18: =ROUND(IF(AH18="SI",W18*$AI$5,0),-3) -> 0 | AJ18: SI | AK18: =IF(AJ18="SI",W18*$AK$5,0) -> 183600 | AL18: =SUMIF('Otras Asesorías y Préstamos'!$B$7:$B$242,B18,'Otras Asesorías y Préstamos'!$F$7:$F$242) -> 0 | AM18: =SUMIF('Otras Asesorías y Préstamos'!$B$7:$B$242,B18,'Otras Asesorías y Préstamos'!$V$7:$V$242) -> 0 | AN18: =ROUND(SUM(W18:AL18),-4) -> 800000
A19: =+A18+1 -> 11 | B19: RESTREPO DE SÁNCHEZ MARÍA ISABEL | C19: =_xlfn.XLOOKUP(B19,Códigos!$B$8:$B$406,Códigos!$A$8:$A$406,"Verificar",0) -> 158 | D19: =_xlfn.XLOOKUP(B19,'Consolidado Cobros'!$B$10:$B$312,'Consolidado Cobros'!$C$10:$C$312,"Verificar",0) -> 21356663 | E19: =IF((MOD((VALUE(MID(TEXT(D19,"000000000000000"),15,1))*3+VALUE(MID(TEXT(D19,"000000000000000"),14,1))*7+VALUE(MID(TEXT(D19,"000000000000000"),13,1))*13+VALUE(MID(TEXT(D19,"000000000000000"),12,1))*17+VALUE(MID(TEXT(D19,"000000000000000"),11,1))*19+VALUE(MID(TEXT(D19,"000000000000000"),10,1))*23+VALUE(MID(TEXT(D19,"000000000000000"),9,1))*29+VALUE(MID(TEXT(D19,"000000000000000"),8,1))*37+VALUE(MID(TEXT(D19,"000000000000000"),7,1))*41+VALUE(MID(TEXT(D19,"000000000000000"),6,1))*43+VALUE(MID(TEXT(D19,"000000000000000"),5,1))*47+VALUE(MID(TEXT(D19,"000000000000000"),4,1))*53+VALUE(MID(TEXT(D19,"000000000000000"),3,1))*59+VALUE(MID(TEXT(D19,"000000000000000"),2,1))*67+VALUE(MID(TEXT(D19,"000000000000000"),1,1))*71),11))=0,0,IF((MOD((VALUE(MID(TEXT(D19,"000000000000000"),15,1))*3+VALUE(MID(TEXT(D19,"000000000000000"),14,1))*7+VALUE(MID(TEXT(D19,"000000000000000"),13,1))*13+VALUE(MID(TEXT(D19,"000000000000000"),12,1))*17+VALUE(MID(TEXT(D19,"000000000000000"),11,1))*19+VALUE(MID(TEXT(D19,"000000000000000"),10,1))*23+VALUE(MID(TEXT(D19,"000000000000000"),9,1))*29+VALUE(MID(TEXT(D19,"000000000000000"),8,1))*37+VALUE(MID(TEXT(D19,"000000000000000"),7,1))*41+VALUE(MID(TEXT(D19,"000000000000000"),6,1))*43+VALUE(MID(TEXT(D19,"000000000000000"),5,1))*47+VALUE(MID(TEXT(D19,"000000000000000"),4,1))*53+VALUE(MID(TEXT(D19,"000000000000000"),3,1))*59+VALUE(MID(TEXT(D19,"000000000000000"),2,1))*67+VALUE(MID(TEXT(D19,"000000000000000"),1,1))*71),11))=1,1,11-(MOD((VALUE(MID(TEXT(D19,"000000000000000"),15,1))*3+VALUE(MID(TEXT(D19,"000000000000000"),14,1))*7+VALUE(MID(TEXT(D19,"000000000000000"),13,1))*13+VALUE(MID(TEXT(D19,"000000000000000"),12,1))*17+VALUE(MID(TEXT(D19,"000000000000000"),11,1))*19+VALUE(MID(TEXT(D19,"000000000000000"),10,1))*23+VALUE(MID(TEXT(D19,"000000000000000"),9,1))*29+VALUE(MID(TEXT(D19,"000000000000000"),8,1))*37+VALUE(MID(TEXT(D19,"000000000000000"),7,1))*41+VALUE(MID(TEXT(D19,"000000000000000"),6,1))*43+VALUE(MID(TEXT(D19,"000000000000000"),5,1))*47+VALUE(MID(TEXT(D19,"000000000000000"),4,1))*53+VALUE(MID(TEXT(D19,"000000000000000"),3,1))*59+VALUE(MID(TEXT(D19,"000000000000000"),2,1))*67+VALUE(MID(TEXT(D19,"000000000000000"),1,1))*71),11)))) -> 8 | F19: =+AN19 -> 1790000 | G19: =+F19*$G$5 -> 340100 | H19: NO | I19: =IF(H19="S",-F19*$I$5,"NO RETENCIÓN") -> NO RETENCIÓN | J19: =+F19+G19 -> 2130100 | K19: =SUM(F19:I19) -> 2130100 | M19: GTFF-169 | N19: Correo | O19: 45987 | R19: =+AM19 -> 0 | T19: Fra con -Ma Isabel Restrepo de S | V19: SI | W19: =ROUND(IF(V19="SI",SUMIF('Facturas año anterior'!$B$8:$B$81,B19,'Facturas año anterior'!$V$8:$V$81)*(100%+$W$5),0),-3)+ROUND(IF(V19="SI",SUMIF('C de C año anterior'!$B$8:$B$210,B19,'C de C año anterior'!$Q$8:$Q$210)*(100%+$W$5),0),-3) -> 1410000 | Y19: =ROUND(IF(X19="SI",W19*$Y$5,0),-3) -> 0 | AA19: =ROUND(IF(Z19="SI",W19*$AA$5,0),-3) -> 0 | AC19: =ROUND(IF(AB19="SI",W19*$AC$5,0),-3) -> 0 | AE19: =ROUND(IF(AD19="SI",W19*$AE$5,0),-3) -> 0 | AG19: =ROUND(IF(AF19="SI",W19*$AG$5,0),-3) -> 0 | AI19: =ROUND(IF(AH19="SI",W19*$AI$5,0),-3) -> 0 | AK19: =IF(AJ19="SI",W19*$AK$5,0) -> 0 | AL19: =SUMIF('Otras Asesorías y Préstamos'!$B$7:$B$242,B19,'Otras Asesorías y Préstamos'!$F$7:$F$242) -> 384583 | AM19: =SUMIF('Otras Asesorías y Préstamos'!$B$7:$B$242,B19,'Otras Asesorías y Préstamos'!$V$7:$V$242) -> 0 | AN19: =ROUND(SUM(W19:AL19),-4) -> 1790000
A20: =+A19+1 -> 12 | B20: RESTREPO MEJÍA MARÍA LUISA | C20: =_xlfn.XLOOKUP(B20,Códigos!$B$8:$B$406,Códigos!$A$8:$A$406,"Verificar",0) -> 159 | D20: =_xlfn.XLOOKUP(B20,'Consolidado Cobros'!$B$10:$B$312,'Consolidado Cobros'!$C$10:$C$312,"Verificar",0) -> 87101474230 | E20: =IF((MOD((VALUE(MID(TEXT(D20,"000000000000000"),15,1))*3+VALUE(MID(TEXT(D20,"000000000000000"),14,1))*7+VALUE(MID(TEXT(D20,"000000000000000"),13,1))*13+VALUE(MID(TEXT(D20,"000000000000000"),12,1))*17+VALUE(MID(TEXT(D20,"000000000000000"),11,1))*19+VALUE(MID(TEXT(D20,"000000000000000"),10,1))*23+VALUE(MID(TEXT(D20,"000000000000000"),9,1))*29+VALUE(MID(TEXT(D20,"000000000000000"),8,1))*37+VALUE(MID(TEXT(D20,"000000000000000"),7,1))*41+VALUE(MID(TEXT(D20,"000000000000000"),6,1))*43+VALUE(MID(TEXT(D20,"000000000000000"),5,1))*47+VALUE(MID(TEXT(D20,"000000000000000"),4,1))*53+VALUE(MID(TEXT(D20,"000000000000000"),3,1))*59+VALUE(MID(TEXT(D20,"000000000000000"),2,1))*67+VALUE(MID(TEXT(D20,"000000000000000"),1,1))*71),11))=0,0,IF((MOD((VALUE(MID(TEXT(D20,"000000000000000"),15,1))*3+VALUE(MID(TEXT(D20,"000000000000000"),14,1))*7+VALUE(MID(TEXT(D20,"000000000000000"),13,1))*13+VALUE(MID(TEXT(D20,"000000000000000"),12,1))*17+VALUE(MID(TEXT(D20,"000000000000000"),11,1))*19+VALUE(MID(TEXT(D20,"000000000000000"),10,1))*23+VALUE(MID(TEXT(D20,"000000000000000"),9,1))*29+VALUE(MID(TEXT(D20,"000000000000000"),8,1))*37+VALUE(MID(TEXT(D20,"000000000000000"),7,1))*41+VALUE(MID(TEXT(D20,"000000000000000"),6,1))*43+VALUE(MID(TEXT(D20,"000000000000000"),5,1))*47+VALUE(MID(TEXT(D20,"000000000000000"),4,1))*53+VALUE(MID(TEXT(D20,"000000000000000"),3,1))*59+VALUE(MID(TEXT(D20,"000000000000000"),2,1))*67+VALUE(MID(TEXT(D20,"000000000000000"),1,1))*71),11))=1,1,11-(MOD((VALUE(MID(TEXT(D20,"000000000000000"),15,1))*3+VALUE(MID(TEXT(D20,"000000000000000"),14,1))*7+VALUE(MID(TEXT(D20,"000000000000000"),13,1))*13+VALUE(MID(TEXT(D20,"000000000000000"),12,1))*17+VALUE(MID(TEXT(D20,"000000000000000"),11,1))*19+VALUE(MID(TEXT(D20,"000000000000000"),10,1))*23+VALUE(MID(TEXT(D20,"000000000000000"),9,1))*29+VALUE(MID(TEXT(D20,"000000000000000"),8,1))*37+VALUE(MID(TEXT(D20,"000000000000000"),7,1))*41+VALUE(MID(TEXT(D20,"000000000000000"),6,1))*43+VALUE(MID(TEXT(D20,"000000000000000"),5,1))*47+VALUE(MID(TEXT(D20,"000000000000000"),4,1))*53+VALUE(MID(TEXT(D20,"000000000000000"),3,1))*59+VALUE(MID(TEXT(D20,"000000000000000"),2,1))*67+VALUE(MID(TEXT(D20,"000000000000000"),1,1))*71),11)))) -> 2 | F20: =+AN20 -> 610000 | G20: =+F20*$G$5 -> 115900 | H20: S | I20: =IF(H20="S",-F20*$I$5,"NO RETENCIÓN") -> -67100 | J20: =+F20+G20 -> 725900 | K20: =SUM(F20:I20) -> 658800 | M20: GTFF-166 | N20: Correo y Wpp | O20: 45974 | R20: =+AM20 -> 0 | T20: Fra con -Cortijo | V20: SI | W20: =ROUND(IF(V20="SI",SUMIF('Facturas año anterior'!$B$8:$B$81,B20,'Facturas año anterior'!$V$8:$V$81)*(100%+$W$5),0),-3)+ROUND(IF(V20="SI",SUMIF('C de C año anterior'!$B$8:$B$210,B20,'C de C año anterior'!$Q$8:$Q$210)*(100%+$W$5),0),-3) -> 612000 | Y20: =ROUND(IF(X20="SI",W20*$Y$5,0),-3) -> 0 | AA20: =ROUND(IF(Z20="SI",W20*$AA$5,0),-3) -> 0 | AC20: =ROUND(IF(AB20="SI",W20*$AC$5,0),-3) -> 0 | AE20: =ROUND(IF(AD20="SI",W20*$AE$5,0),-3) -> 0 | AG20: =ROUND(IF(AF20="SI",W20*$AG$5,0),-3) -> 0 | AI20: =ROUND(IF(AH20="SI",W20*$AI$5,0),-3) -> 0 | AK20: =IF(AJ20="SI",W20*$AK$5,0) -> 0 | AL20: =SUMIF('Otras Asesorías y Préstamos'!$B$7:$B$242,B20,'Otras Asesorías y Préstamos'!$F$7:$F$242) -> 0 | AM20: =SUMIF('Otras Asesorías y Préstamos'!$B$7:$B$242,B20,'Otras Asesorías y Préstamos'!$V$7:$V$242) -> 0 | AN20: =ROUND(SUM(W20:AL20),-4) -> 610000
